Workbook
Name IndustrySector: 'Industry List'!$B$3:$B$110
Name NonUKCountry: 'Country List'!$E$4:$E$239

Sheet Front Page
A1: Office for National Statistics: Front page
B3: 2021
B4: l Notice is given under section 1 of the Statistics of Trade Act 1947.
B5: l If you do not complete and return this questionnaire, penalties may be incurred (under section 4 of the Statistics of Trade Act 1947).
B6: l All the information you provide is kept strictly confidential. It is illegal for us to reveal your data or identify your business to unauthorised persons.
B8: Please read this page and the 'General Instructions' tab before answering any questions, as they contain useful information on how best to complete this questionnaire. The 'Help' tab contains question specific information which can be consulted if further explanation or detail is required.
B10: Purpose of this Survey
B11: The purpose of this survey is to collect data on assets and liabilities of foreign parent companies in their UK affiliates and branches and the investment positions and transactions related to those assets and liabilities. Data from this survey is used to measure earnings, transactions and levels of investment by immediate foreign parent companies in their UK affiliates.
B14: Your data will contribute to an essential measurement of the UK's Balance of Payments. Details on the publication of this data can be found at www.statistics.gov.uk. For further information regarding Foreign Direct Investment (FDI), please refer to the Organisation for Economic Cooperation and Development (OECD) Benchmark Definition of FDI (fourth Edition).
B18: Definition of UK
B19: The UK includes England, Scotland, Wales and Northern Ireland but excludes the Channel Islands and the Isle of Man. For purposes of oil and mineral exploration and extraction the UK includes the UK continental shelf.
B21: Exclude: Data relating only to UK parents of the UK affiliate company.
B23: What ONS requires:
B24: - Where there is more than one UK-resident company or branch within the enterprise group, you are asked to complete the questionnaire on behalf of the entire group of UK companies.
... B44: * This spreadsheet must be uploaded to SDC on completion *

Sheet General Instructions
B1: Advice on completing the Questionnaire
B3: You should complete this questionnaire if you are:
B4: - an independent UK company, or
B5: - the senior company in a group of UK companies, or
B6: - a holding company for one or more UK companies, or
B7: - a branch of a foreign company or foreign Head Office
B8: and
B9: - a foreign company owns 10% or more of your equity capital.
B11: We require data for:
B12: - your company
B13: - any immediate UK or foreign affiliate or branch of your UK company
B14: - any fellow enterprise with outstanding intercompany or branch head balances
... B25: This questionnaire is split into the following sections:
B27: Section | C27: Description
B28: Contact details | C28: -
B29: Section A | C29: Reporting Period and Company Share Status
B30: Section B | C30: Business Structure
B31: Section C | C31: Immediate Foreign Parent Company, Head Office or Fellow Enterprise Details
B32: Section D | C32: Earnings & Dividends
B33: Section E | C33: Quoted Equity Capital Transactions and Balance Sheet
B34: Section F | C34: Unquoted Equity Capital Transactions and Balance Sheet
B35: Section G | C35: Preference Shares and Debt Attributable to the Immediate Foreign Parent Company
B36: Section H | C36: Balance Sheet Intercompany Loans and Current Account
B37: Section I | C37: Branch Earnings, Assets and Liabilities
B38: Section J | C38: Re-invested / Retained earnings
... B40: Section L | C40: Comments
B42: Please note, changes have been made to the questionnaire from the Annual 2020 reporting period.
B44: New questions have been added to the following sections:
B45: - Section D
B46: - Section E
B47: - Section F
B49: We have also added the following new sections:
B50: - Section J
B51: - Section K
B53: The fundamental FDI concept is of a chain of investment leading away from a single investor.
B54: This can be in either or both directions i.e. inward and/or outward. The basic FDI relationship links are :
B55: FDI Relationship | C55: Share holding with voting rights equal to or greater than | D55: Share holding with voting rights equal to or less than
B57: Affiliate | C57: 0.1 | D57: 1
B58: Associate | C58: 0.1 | D58: 0.5
B59: Subsidiary | C59: 0.501 | D59: 1
...

Sheet Questionnaire
A1: 062:0105 | B1: Annual Inward Foreign Direct Investment Survey | D1: 2021 | E1: Report monetary figures to the nearest £0.1 million
C2: Please begin by inserting your contact details
C3: Contact details
C4: Please insert the details of the person we should contact if we have any queries regarding the figures returned on this questionnaire.
B5: Company* | C5: Company A
A6: 9020 | B6: Contact* | C6: Colin McColin
A7: 9030 | B7: Tel. No* | C7: 0111 1111111
A8: 9040 | B8: Fax
A9: 9050 | B9: E-Mail* | C9: colin.mccolin@doogle.com
B10: Date
B11: Website
C12: You must complete all entries indicated by a * above, before continuing
C13: Section A - Reporting Period and Company Share Status
C14: Data should be provided from your own accounting systems.
C15: Please report for the period 01/01/2021 to 31/12/2021
A16: 0411 | B16: 1 | C16: If you are unable to report figures for the above period, please give the start date for the reporting period which you are supplying data for. Please use the format dd/mm/yyyy.
A17: 0412 | C17: Please give the end date for the reporting period which you are supplying data for. Please use the format dd/mm/yyyy.
A18: 0421 | B18: 2 | C18: What is the year(s) of your annual accounting period for your published statutory accounts? (Please select from the drop down) | D18: 2021
A19: 0315 | B19: 3 | C19: Are the shares of the UK company quoted on the London Stock Exchange? (Please select from the drop down) | D19: No (unquoted affiliate)
C21: Section B - Business Structure
C22: For this section of the questionnaire you are being asked questions around ownership of companies and therefore we are asking you to provide figures as a percentage of voting power. From question 16 onwards, we move away from questions on voting power and you will be asked to answer questions with regards to voting share capital. (Voting share capital refers directly to the share equity in a company.)
C23: Ultimate Parent Company
C24: The ultimate parent company is the one that is at the top of the ownership chain, i.e. not controlled by any other entity.
C25: If your immediate foreign parent company is also your ultimate parent company, please provide their details for both the ‘ultimate parent company’ questions, and the ‘immediate foreign parent company’ questions.
A26: 0218 | B26: 4 | C26: What is the legal name of your ultimate parent company? | D26: Acme Ltd
A27: 0219 | B27: 5 | C27: What is the country of residence of your ultimate parent company? (Please select from the drop down) | D27: CHRISTMAS ISLAND
A28: 0228 | B28: 6 | C28: What is the primary industry sector for your ultimate parent company? (Please select from the drop down) | D28: Forestry & logging
A29: 3733 | B29: 7 | C29: What percentage of the UK affiliate company's voting power is held by the ultimate parent company? | D29: 100
C30: Voting Power Generally, ordinary shares provide voting power (the measure of control of a company). While voting power is often obtained through the purchase of equity, it is possible to have voting power that is not the same proportion as equity ownership. This is mainly the case where there are different classes of shares such as 'A' and 'B' class shares, where A may have a higher weight of voting power (control) than the B class of shares. It is also possible to obtain voting power without purchasing equity (for example through repurchase agreements). Note: for a branch voting power will automatically be 100%.
C31: Immediate Foreign Affiliate(s) Affiliate is used as an umbrella term covering both subsidiaries (where the investor holds more than 50% of the voting power) and associates (where the investor holds between 10% and 50%). An immediate foreign affiliate company is the first foreign (non-UK) affiliate in which your company holds at least 10% of the voting power. Your company is a foreign affiliate if a foreign company holds at least 10% of your voting power.
A32: 0231 | B32: 8 | C32: In how many immediate foreign affiliate companies (outward investment) does the UK affiliate company directly or indirectly invest (with a shareholding with a voting power of 10% or more)? | D32: 10
C33: Immediate Foreign Parent(s)
C34: An immediate foreign parent is the first foreign (i.e. non-UK) business which holds 10% or more voting power within your company. It is possible for there to be more than one immediate foreign parent company.
A35: 0232 | B35: 9 | C35: How many immediate foreign parent companies have holdings of 10% or more voting power within your company? | D35: 1
C36: The remainder of this questionnaire asks you to provide details of your immediate foreign parent company or head office, or a fellow enterprise. If you have more than one immediate foreign parent company, or fellow enterprise relationship, a separate column must be completed for each of these entities.
C37: Section C - Immediate Foreign Parent Company, Head Office or Fellow Enterprise Details | D37: 1 | E37: 2 | F37: 3 | G37: 4 | H37: 5 | I37: 6 | J37: 7 | K37: 8 | L37: 9 | M37: 10 | N37: 11 | O37: 12 | P37: 13 | Q37: 14 | R37: 15 | S37: 16 | T37: 17 | U37: 18 | V37: 19 | W37: 20 | X37: 21 | Y37: 22 | Z37: 23 | AA37: 24 | AB37: 25 | AC37: 26 | AD37: 27 | AE37: 28 | AF37: 29 | AG37: 30 | AH37: 31 | AI37: 32 | AJ37: 33 | AK37: 34 | AL37: 35 | AM37: 36 | AN37: 37 | AO37: 38 | AP37: 39 | AQ37: 40 | AR37: 41 | AS37: 42 | AT37: 43 | AU37: 44 | AV37: 45 | AW37: 46 | AX37: 47 | AY37: 48 | AZ37: 49 | BA37: 50 | BB37: 51 | BC37: 52 | BD37: 53 | BE37: 54 | BF37: 55 | BG37: 56 | BH37: 57 | BI37: 58 | BJ37: 59 | BK37: 60 | BL37: 61 | BM37: 62 | BN37: 63 | BO37: 64 | BP37: 65 | BQ37: 66 | BR37: 67 | BS37: 68 | BT37: 69 | BU37: 70 | BV37: 71 | BW37: 72 | BX37: 73 | BY37: 74 | BZ37: 75 | CA37: 76 | CB37: 77 | CC37: 78 | CD37: 79 | CE37: 80 | CF37: 81 | CG37: 82 | CH37: 83 | CI37: 84 | CJ37: 85 | CK37: 86 | CL37: 87 | CM37: 88 | CN37: 89 | CO37: 90 | CP37: 91 | CQ37: 92 | CR37: 93 | CS37: 94 | CT37: 95 | CU37: 96 | CV37: 97 | CW37: 98 | CX37: 99 | CY37: 100 | CZ37: 101 | DA37: 102 | DB37: 103 | DC37: 104 | DD37: 105 | DE37: 106 | DF37: 107 | DG37: 108 | DH37: 109 | DI37: 110 | DJ37: 111 | DK37: 112 | DL37: 113 | DM37: 114 | DN37: 115 | DO37: 116 | DP37: 117 | DQ37: 118 | DR37: 119 | DS37: 120 | DT37: 121 | DU37: 122 | DV37: 123 | DW37: 124 | DX37: 125 | DY37: 126 | DZ37: 127 | EA37: 128 | EB37: 129 | EC37: 130 | ED37: 131 | EE37: 132 | EF37: 133 | EG37: 134 | EH37: 135 | EI37: 136 | EJ37: 137 | EK37: 138 | EL37: 139 | EM37: 140 | EN37: 141 | EO37: 142 | EP37: 143 | EQ37: 144 | ER37: 145 | ES37: 146 | ET37: 147 | EU37: 148 | EV37: 149 | EW37: 150 | EX37: 151 | EY37: 152 | EZ37: 153 | FA37: 154 | FB37: 155 | FC37: 156 | FD37: 157 | FE37: 158 | FF37: 159 | FG37: 160 | FH37: 161 | FI37: 162 | FJ37: 163 | FK37: 164 | FL37: 165 | FM37: 166 | FN37: 167 | FO37: 168 | FP37: 169 | FQ37: 170 | FR37: 171 | FS37: 172 | FT37: 173 | FU37: 174 | FV37: 175 | FW37: 176 | FX37: 177 | FY37: 178 | FZ37: 179 | GA37: 180 | GB37: 181 | GC37: 182 | GD37: 183 | GE37: 184 | GF37: 185 | GG37: 186 | GH37: 187 | GI37: 188 | GJ37: 189 | GK37: 190 | GL37: 191 | GM37: 192 | GN37: 193 | GO37: 194 | GP37: 195 | GQ37: 196 | GR37: 197 | GS37: 198 | GT37: 199 | GU37: 200 | GV37: 201 | GW37: 202 | GX37: 203 | GY37: 204 | GZ37: 205 | HA37: 206 | HB37: 207 | HC37: 208 | HD37: 209 | HE37: 210 | HF37: 211 | HG37: 212 | HH37: 213 | HI37: 214 | HJ37: 215 | HK37: 216 | HL37: 217 | HM37: 218 | HN37: 219 | HO37: 220 | HP37: 221 | HQ37: 222 | HR37: 223 | HS37: 224 | HT37: 225 | HU37: 226 | HV37: 227 | HW37: 228 | HX37: 229 | HY37: 230 | HZ37: 231 | IA37: 232 | IB37: 233 | IC37: 234 | ID37: 235 | IE37: 236 | IF37: 237 | IG37: 238 | IH37: 239 | II37: 240 | IJ37: 241 | IK37: 242 | IL37: 243 | IM37: 244 | IN37: 245 | IO37: 246 | IP37: 247 | IQ37: 248 | IR37: 249 | IS37: 250
A38: 0211 | B38: 10 | C38: What is the legal name of your immediate foreign parent company, head office or fellow enterprise? | D38: Parent Company A
A39: 0601 | B39: 11 | C39: Is the foreign entity named in question 10 an immediate foreign parent, head office or a fellow enterprise of the UK company or branch? (Please select from the drop down) | D39: Foreign Parent
A40: 0505 | B40: 12 | C40: Is your immediate foreign parent company, head office or fellow enterprise a type of holding company specifically set up for passing investments through its country of residence rather than being the primary destination of such investment? (Please select from the drop down) | D40: Yes
A41: 0212 | B41: 13 | C41: What is the country of residence of your immediate foreign parent company, head office or fellow enterprise? (Please select from the drop down) | D41: CANADA
...

Sheet Help
A1: Questions | C1: Help with questions
A3: Contact details
B4: Please insert the details of the person we should contact if we have any queries regarding the figures returned on this questionnaire.
A5: Company* | C5: Company legal name. Mandatory. Don’t use ‘,’ or ‘|’.
A6: Contact* | C6: Contact name. Mandatory.
A7: Tel. No* | C7: Telephone number. Mandatory.
A8: Fax
A9: E-Mail* | C9: E-mail. Mandatory.
A10: Date
A11: Website
B13: Section A - Reporting Period
B14: Data should be provided from your own accounting systems.
B15: Please report for the period 01/01/2021 to 31/12/2021
A16: 1 | B16: If you are unable to report figures for the above period, please give the start date for the reporting period which you are supplying data for. Please use the format dd/mm/yyyy. | C16: The majority of the year you are supplying data for should be within the year we have specified. We cannot accept data relating to earlier years as such a return would distort the final Balance of Payments results.
B17: Please give the end date for the reporting period which you are supplying data for. Please use the format dd/mm/yyyy.
A18: 2 | B18: What is the year(s) of your annual accounting period for your published statutory accounts? (Please select from the drop down) | C18: The ONS use this to correlate the quarterly and annual datasets prepared from your data.
A19: 3 | B19: Are the shares of the UK company quoted on the London Stock Exchange? (Please select from the drop down) | C19: If the UK company is quoted or listed on the London Stock Exchange please select the appropriate answer from the dropdown list: 'Yes (quoted affiliate)', 'No (unquoted affiliate)' or 'N/A (branch)'.
B21: Section B - Business Structure
B22: For this section of the questionnaire you are being asked questions around ownership of companies and therefore we are asking you to provide figures as a percentage of voting power. From question 16 onwards, we move away from questions on voting power and you will be asked to answer questions with regards to voting share capital. (Voting share capital refers directly to the share equity in a company.)
B23: Ultimate Parent Company
B24: The ultimate parent company is the one that is at the top of the ownership chain,
B25: i.e. not controlled by any other entity. If your immediate foreign parent company is also your ultimate parent company, please provide their details for both the ‘ultimate parent company’ questions, and the ‘immediate foreign parent company’ questions.
A26: 4 | B26: What is the legal name of your ultimate parent company? | C26: If you have more than one ultimate parent please contact the ONS. Don’t use ‘,’ or ‘|’.
A27: 5 | B27: What is the country of residence of your ultimate parent company? (Please select from the drop down) | C27: Residence is defined in paragraph 73 of the International Monetary Fund Balance of Payments Manual 5 as follows: ‘An enterprise is said to have a centre of economic interest and to be a resident unit of a country (economic territory) when the enterprise is engaged in a significant amount of production of goods and/or services there or when the enterprise owns land or buildings located there. The enterprise must maintain at least one production establishment in the country and must plan to operate the establishment indefinitely or over a long period of time’. Please note that in this context 'production' refers to all forms of economic activity - not simply the production of goods. This country must be outside of the United Kingdom, but can include the Isle of Man, Jersey, Guernsey or any of the other Channel Islands.
A28: 6 | B28: What is the primary industry sector for your ultimate parent company? (Please select from the drop down) | C28: The primary industry sector codes are as defined in the 'UK Standard Industrial Classification of Economic Activities 2007' published by ONS. There are some subdivisions for the banking and security dealer sectors. See ONS web site for comprehensive classification list: https://www.ons.gov.uk/methodology/classificationsandstandards/ukstandardindustrialclassificationofeconomicactivities/uksic2007 If you require an SIC code, please see the resources available on the above page, including the SIC Main Volume (PDF 1,294 KB), Index (XLS 2,919 KB) and Interactive Hierarchy.
A29: 7 | B29: What percentage of the UK affiliate company's voting power is held by the ultimate parent company?
B30: Voting Power Generally, ordinary shares provide voting power (the measure of control of a company). While voting power is often obtained through the purchase of equity, it is possible to have voting power that is not the same proportion as equity ownership. This is mainly the case where there are different classes of shares such as 'A' and 'B' class shares, where A may have a higher weight of voting power (control) than the B class of shares. It is also possible to obtain voting power without purchasing equity (for example through repurchase agreements). Note: for a branch voting power will automatically be 100%.
B31: Immediate Foreign Affiliate(s) Affiliate is used as an umbrella term covering both subsidiaries (where the investor holds more than 50% of the voting power) and associates (where the investor holds between 10% and 50%). An immediate foreign affiliate company is the first foreign (non-UK) affiliate in which your company holds at least 10% of the voting power. Your company is a foreign affiliate if a foreign company holds at least 10% of your voting power.
A32: 8 | B32: In how many immediate foreign affiliate companies (outward investment) does the UK affiliate company directly or indirectly invest (with a shareholding with a voting power of 10% or more)?
B33: Immediate Foreign Parent(s)
B34: An immediate foreign parent is the first foreign (i.e. non-UK) business which holds 10% or more voting power within your company. It is possible for there to be more than one immediate foreign parent company.
A35: 9 | B35: How many immediate foreign parent companies have holdings of 10% or more voting power within your company?
B36: The remainder of this questionnaire asks you to provide details of your immediate foreign parent company or head office, or a fellow enterprise. If you have more than one immediate foreign parent company, or fellow enterprise relationship, a separate column must be completed for each of these entities.
B37: Section C - Immediate Foreign Parent Company, Head Office or Fellow Enterprise Details
A38: 10 | B38: What is the legal name of your immediate foreign parent company, head office or fellow enterprise? | C38: Company legal name. Don’t use ‘,’ or ‘|’.
A39: 11 | B39: Is the foreign entity named in question 10 an immediate foreign parent, head office or a fellow enterprise of the UK company or branch? (Please select from the drop down)
A40: 12 | B40: Is your immediate foreign parent company, head office or fellow enterprise a type of holding company specifically set up for passing investments through its country of residence rather than being the primary destination of such investment? (Please select from the drop down) | C40: In FDI terms, an overseas holding company is defined as a company set up for purposes of passing investments through the resident country rather than being the primary destination of such investment.
A41: 13 | B41: What is the country of residence of your immediate foreign parent company, head office or fellow enterprise? (Please select from the drop down) | C41: Residence is defined in paragraph 73 of the International Monetary Fund Balance of Payments Manual 5 as follows. ‘An enterprise is said to have a centre of economic interest and to be a resident unit of a country (economic territory) when the enterprise is engaged in a significant amount of production of goods and/or services there or when the enterprise owns land or buildings located there. The enterprise must maintain at least one production establishment in the country and must plan to operate the establishment indefinitely or over a long period of time’. Please note that in this context 'production' refers to all forms of economic activity - not simply the production of goods. This country must be outside of the United Kingdom, but can include the Isle of Man, Jersey, Guernsey or any of the other Channel Islands.
A42: 14 | B42: What is the primary industry sector of your immediate foreign parent company, head office or fellow enterprise? (Please select from the drop down) | C42: The primary industry sector codes are as defined in the 'UK Standard Industrial Classification of Economic Activities 2007' published by ONS. There are some subdivisions for the banking and security dealer sectors. See ONS web site for comprehensive classification list: https://www.ons.gov.uk/methodology/classificationsandstandards/ukstandardindustrialclassificationofeconomicactivities/uksic2007 If you require an SIC code, please see the resources available on the above page, including the SIC Main Volume (PDF 1,294 KB), Index (XLS 2,919 KB) and Interactive Hierarchy.
B43: Branch For FDI a branch is a permanent establishment but not a separate legal entity. Such establishments should either have a complete set of accounts or be able to compile a meaningful set of accounts, from both an economic and legal viewpoint. A branch is controlled by the 'Head Office' of the parent company.
...

Sheet Validation
A1: Validation Queries
A4: Validation queries may have occurred. Please check your responses and amend them where necessary.
A5: ERROR - data has not been entered where a blank entry is not acceptable.
A6: QUERY - data entered does not correlate with other entries and requires correction or explanation.
A7: WARNING - data entered is unusually high or low - please check your entry and confirm if correct.
A8: If the data is correct please comment on the reasons in the comments box at the bottom of the Questionnaire tab.
A9: This will avoid you being contacted for clarification.
A12: =IF(AND(Questionnaire!C5<>0, Questionnaire!C6<>0, Questionnaire!C7<>0, Questionnaire!C9<>0),"OK Contact Details","ERROR Contact Details - You have not completed all of the compulsory contact details") -> OK Contact Details | B12: =IF(LEFT(A12,2)="OK",0,IF(LEFT(A12,2)="ER",2,1)) -> 0 | C12: =IF(AND(Questionnaire!C5<>0,LEN(Questionnaire!C5)<1001, Questionnaire!C6<>0,LEN(Questionnaire!C6)<1001, Questionnaire!C7<>0,LEN(Questionnaire!C7)<1001, Questionnaire!C9<>0,LEN(Questionnaire!C9)<1001),"OK Contact Details Length","ERROR Contact Details - Too many characters in a field") -> OK Contact Details Length
A13: =IF(Questionnaire!D18=0,"ERROR Q 2 - Annual accounting period - You have not completed this question","OK Q 2") -> OK Q 2 | B13: =IF(LEFT(A13,2)="OK",0,IF(LEFT(A13,2)="ER",2,1)) -> 0
A14: =IF(Questionnaire!D19<>0=TRUE,"OK Q 3", "ERROR Q 3 - Quoted or Unquoted company - You must answer 'Yes' or 'No' to Q3") -> OK Q 3 | B14: =IF(LEFT(A14,2)=0,"OK",IF(LEFT(A14,2)="ER",2,1)) -> 1
A15: =IF(Questionnaire!D27<>0=TRUE,IF(COUNTIF('Country List'!$B$4:$B$240,Questionnaire!D27)=0,"ERROR Q 5 - This must match a country option from the drop-down list","OK Q 5"),"ERROR Q 5 - This must match a country option from the drop-down list") -> OK Q 5 | B15: =IF(LEFT(A15,2)=0,"OK",IF(LEFT(A15,2)="ER",2,1)) -> 1
A16: =IF(Questionnaire!D28<>0=TRUE,IF(COUNTIF('Industry List'!$B$3:$B$110,Questionnaire!D28)=0,"ERROR Q 6 - This must match an industry option from the drop-down list","OK Q 6"),"ERROR Q 6 - This must match an industry option from the drop-down list") -> OK Q 6 | B16: =IF(LEFT(A16,2)=0,"OK",IF(LEFT(A16,2)="ER",2,1)) -> 1
A17: =IF(ISNUMBER(Questionnaire!D32),"OK Q 8","ERROR Q 8 - Number of immediate foreign affiliates - You have not completed this question") -> OK Q 8 | B17: =IF(LEFT(A17,2)=0,"OK",IF(LEFT(A17,2)="ER",2,1)) -> 1
E18: =IF(OR(Questionnaire!G19="N/A (branch)"=TRUE,Questionnaire!G47="Branch"=TRUE),"OK Qu 3/24",IF(AND(Questionnaire!G19<>0=TRUE,Questionnaire!G75<>0=TRUE),"ERROR Qu 3/24 - Quoted or Unquoted company - You must answer 'Yes' or 'No' to Q3 and Q24", "OK Qu 3/24")) -> OK Qu 3/24
A19: =IF(ISNUMBER(Questionnaire!D35),"OK Q 9","ERROR Q 9 - Number of immediate foreign parents - You have not completed this question") -> OK Q 9 | B19: =IF(LEFT(A19,2)=0,"OK",IF(LEFT(A19,2)="ER",2,1)) -> 1
A20: =IF(LEFT(A21,2)="OK",1,IF(LEFT(A21,2)="ER",2,1)) -> 1 | B20: =IF(LEFT(B21,2)="OK",1,IF(LEFT(B21,2)="ER",2,1)) -> 1 | C20: =IF(LEFT(C21,2)="OK",1,IF(LEFT(C21,2)="ER",2,1)) -> 1 | D20: =IF(LEFT(D21,2)="OK",1,IF(LEFT(D21,2)="ER",2,1)) -> 1 | E20: =IF(LEFT(E21,2)="OK",1,IF(LEFT(E21,2)="ER",2,1)) -> 1 | F20: =IF(LEFT(F21,2)="OK",1,IF(LEFT(F21,2)="ER",2,1)) -> 1 | G20: =IF(LEFT(G21,2)="OK",1,IF(LEFT(G21,2)="ER",2,1)) -> 1 | H20: =IF(LEFT(H21,2)="OK",1,IF(LEFT(H21,2)="ER",2,1)) -> 1 | ... IP20: =IF(LEFT(IP21,2)="OK",1,IF(LEFT(IP21,2)="ER",2,1)) -> 1
A21: =IF(Questionnaire!D38>0 = TRUE, "OK Q 12", IF(OR(Questionnaire!D40="Yes",Questionnaire!D40="No"),"OK Q 12","ERROR Q 12 - You must enter 'Yes' or 'No' ")) -> OK Q 12 | B21: =IF(Questionnaire!E40<>0 = FALSE, "OK Q 12", IF(OR(Questionnaire!E40="Yes",Questionnaire!E40="No"),"OK Q 12","ERROR Q 12 - You must enter 'Yes' or 'No' ")) -> OK Q 12 | C21: =IF(Questionnaire!F40<>0 = FALSE, "OK Q 12", IF(OR(Questionnaire!F40="Yes",Questionnaire!F40="No"),"OK Q 12","ERROR Q 12 - You must enter 'Yes' or 'No' ")) -> OK Q 12 | D21: =IF(Questionnaire!G40<>0 = FALSE, "OK Q 12", IF(OR(Questionnaire!G40="Yes",Questionnaire!G40="No"),"OK Q 12","ERROR Q 12 - You must enter 'Yes' or 'No' ")) -> OK Q 12 | E21: =IF(Questionnaire!H40<>0 = FALSE, "OK Q 12", IF(OR(Questionnaire!H40="Yes",Questionnaire!H40="No"),"OK Q 12","ERROR Q 12 - You must enter 'Yes' or 'No' ")) -> OK Q 12 | F21: =IF(Questionnaire!I40<>0 = FALSE, "OK Q 12", IF(OR(Questionnaire!I40="Yes",Questionnaire!I40="No"),"OK Q 12","ERROR Q 12 - You must enter 'Yes' or 'No' ")) -> OK Q 12 | G21: =IF(Questionnaire!J40<>0 = FALSE, "OK Q 12", IF(OR(Questionnaire!J40="Yes",Questionnaire!J40="No"),"OK Q 12","ERROR Q 12 - You must enter 'Yes' or 'No' ")) -> OK Q 12 | H21: =IF(Questionnaire!K40<>0 = FALSE, "OK Q 12", IF(OR(Questionnaire!K40="Yes",Questionnaire!K40="No"),"OK Q 12","ERROR Q 12 - You must enter 'Yes' or 'No' ")) -> OK Q 12 | I21: =IF(Questionnaire!L40<>0 = FALSE, "OK Q 12", IF(OR(Questionnaire!L40="Yes",Questionnaire!L40="No"),"OK Q 12","ERROR Q 12 - You must enter 'Yes' or 'No' ")) -> OK Q 12 | ... IP21: =IF(Questionnaire!IS40<>0 = FALSE, "OK Q 12", IF(OR(Questionnaire!IS40="Yes",Questionnaire!IS40="No"),"OK Q 12","ERROR Q 12 - You must enter 'Yes' or 'No' ")) -> OK Q 12
A22: =IF(LEFT(A23,2)="OK",1,IF(LEFT(A23,2)="ER",2,1)) -> 1 | B22: =IF(LEFT(B23,2)="OK",1,IF(LEFT(B23,2)="ER",2,1)) -> 1 | C22: =IF(LEFT(C23,2)="OK",1,IF(LEFT(C23,2)="ER",2,1)) -> 1 | D22: =IF(LEFT(D23,2)="OK",1,IF(LEFT(D23,2)="ER",2,1)) -> 1 | E22: =IF(LEFT(E23,2)="OK",1,IF(LEFT(E23,2)="ER",2,1)) -> 1 | F22: =IF(LEFT(F23,2)="OK",1,IF(LEFT(F23,2)="ER",2,1)) -> 1 | G22: =IF(LEFT(G23,2)="OK",1,IF(LEFT(G23,2)="ER",2,1)) -> 1 | H22: =IF(LEFT(H23,2)="OK",1,IF(LEFT(H23,2)="ER",2,1)) -> 1 | ... IP22: =IF(LEFT(IP23,2)="OK",1,IF(LEFT(IP23,2)="ER",2,1)) -> 1
A23: =IF(Questionnaire!D41<>0 = FALSE, "OK Q 13", IF(COUNTIF('Country List'!$E$4:$E$239,Questionnaire!D41)=0,"ERROR Q 13 - This must match a country option from the drop-down list","OK Q 13")) -> OK Q 13 | B23: =IF(Questionnaire!E41<>0 = FALSE, "OK Q 13", IF(COUNTIF('Country List'!$E$4:$E$239,Questionnaire!E41)=0,"ERROR Q 13 - This must match a country option from the drop-down list","OK Q 13")) -> OK Q 13 | C23: =IF(Questionnaire!F41<>0 = FALSE, "OK Q 13", IF(COUNTIF('Country List'!$E$4:$E$239,Questionnaire!F41)=0,"ERROR Q 13 - This must match a country option from the drop-down list","OK Q 13")) -> OK Q 13 | D23: =IF(Questionnaire!G41<>0 = FALSE, "OK Q 13", IF(COUNTIF('Country List'!$E$4:$E$239,Questionnaire!G41)=0,"ERROR Q 13 - This must match a country option from the drop-down list","OK Q 13")) -> OK Q 13 | E23: =IF(Questionnaire!H41<>0 = FALSE, "OK Q 13", IF(COUNTIF('Country List'!$E$4:$E$239,Questionnaire!H41)=0,"ERROR Q 13 - This must match a country option from the drop-down list","OK Q 13")) -> OK Q 13 | F23: =IF(Questionnaire!I41<>0 = FALSE, "OK Q 13", IF(COUNTIF('Country List'!$E$4:$E$239,Questionnaire!I41)=0,"ERROR Q 13 - This must match a country option from the drop-down list","OK Q 13")) -> OK Q 13 | G23: =IF(Questionnaire!J41<>0 = FALSE, "OK Q 13", IF(COUNTIF('Country List'!$E$4:$E$239,Questionnaire!J41)=0,"ERROR Q 13 - This must match a country option from the drop-down list","OK Q 13")) -> OK Q 13 | H23: =IF(Questionnaire!K41<>0 = FALSE, "OK Q 13", IF(COUNTIF('Country List'!$E$4:$E$239,Questionnaire!K41)=0,"ERROR Q 13 - This must match a country option from the drop-down list","OK Q 13")) -> OK Q 13 | ... IP23: =IF(Questionnaire!IS41<>0 = FALSE, "OK Q 13", IF(COUNTIF('Country List'!$E$4:$E$239,Questionnaire!IS41)=0,"ERROR Q 13 - This must match a country option from the drop-down list","OK Q 13")) -> OK Q 13
A24: =IF(LEFT(A25,2)="OK",1,IF(LEFT(A25,2)="ER",2,1)) -> 1 | B24: =IF(LEFT(B25,2)="OK",1,IF(LEFT(B25,2)="ER",2,1)) -> 1 | C24: =IF(LEFT(C25,2)="OK",1,IF(LEFT(C25,2)="ER",2,1)) -> 1 | D24: =IF(LEFT(D25,2)="OK",1,IF(LEFT(D25,2)="ER",2,1)) -> 1 | E24: =IF(LEFT(E25,2)="OK",1,IF(LEFT(E25,2)="ER",2,1)) -> 1 | F24: =IF(LEFT(F25,2)="OK",1,IF(LEFT(F25,2)="ER",2,1)) -> 1 | G24: =IF(LEFT(G25,2)="OK",1,IF(LEFT(G25,2)="ER",2,1)) -> 1 | H24: =IF(LEFT(H25,2)="OK",1,IF(LEFT(H25,2)="ER",2,1)) -> 1 | ... IP24: =IF(LEFT(IP25,2)="OK",1,IF(LEFT(IP25,2)="ER",2,1)) -> 1
A25: =IF(Questionnaire!D42<>0 = FALSE, "OK Q 14", IF(COUNTIF('Industry List'!$B$3:$B$110,Questionnaire!D42)=0,"ERROR Q 14 - This must match an industry option from the drop-down list","OK Q 14")) -> OK Q 14 | B25: =IF(Questionnaire!E42<>0 = FALSE, "OK Q 14", IF(COUNTIF('Industry List'!$B$3:$B$110,Questionnaire!E42)=0,"ERROR Q 14 - This must match an industry option from the drop-down list","OK Q 14")) -> OK Q 14 | C25: =IF(Questionnaire!F42<>0 = FALSE, "OK Q 14", IF(COUNTIF('Industry List'!$B$3:$B$110,Questionnaire!F42)=0,"ERROR Q 14 - This must match an industry option from the drop-down list","OK Q 14")) -> OK Q 14 | D25: =IF(Questionnaire!G42<>0 = FALSE, "OK Q 14", IF(COUNTIF('Industry List'!$B$3:$B$110,Questionnaire!G42)=0,"ERROR Q 14 - This must match an industry option from the drop-down list","OK Q 14")) -> OK Q 14 | E25: =IF(Questionnaire!H42<>0 = FALSE, "OK Q 14", IF(COUNTIF('Industry List'!$B$3:$B$110,Questionnaire!H42)=0,"ERROR Q 14 - This must match an industry option from the drop-down list","OK Q 14")) -> OK Q 14 | F25: =IF(Questionnaire!I42<>0 = FALSE, "OK Q 14", IF(COUNTIF('Industry List'!$B$3:$B$110,Questionnaire!I42)=0,"ERROR Q 14 - This must match an industry option from the drop-down list","OK Q 14")) -> OK Q 14 | G25: =IF(Questionnaire!J42<>0 = FALSE, "OK Q 14", IF(COUNTIF('Industry List'!$B$3:$B$110,Questionnaire!J42)=0,"ERROR Q 14 - This must match an industry option from the drop-down list","OK Q 14")) -> OK Q 14 | H25: =IF(Questionnaire!K42<>0 = FALSE, "OK Q 14", IF(COUNTIF('Industry List'!$B$3:$B$110,Questionnaire!K42)=0,"ERROR Q 14 - This must match an industry option from the drop-down list","OK Q 14")) -> OK Q 14 | ... IP25: =IF(Questionnaire!IS42<>0 = FALSE, "OK Q 14", IF(COUNTIF('Industry List'!$B$3:$B$110,Questionnaire!IS42)=0,"ERROR Q 14 - This must match an industry option from the drop-down list","OK Q 14")) -> OK Q 14
A26: =IF(LEFT(A27,2)="OK",0,IF(LEFT(A27,2)="WA",2,1)) -> 0 | B26: =IF(LEFT(B27,2)="OK",0,IF(LEFT(B27,2)="WA",2,1)) -> 0 | C26: =IF(LEFT(C27,2)="OK",0,IF(LEFT(C27,2)="WA",2,1)) -> 0 | D26: =IF(LEFT(D27,2)="OK",0,IF(LEFT(D27,2)="WA",2,1)) -> 0 | E26: =IF(LEFT(E27,2)="OK",0,IF(LEFT(E27,2)="WA",2,1)) -> 0 | F26: =IF(LEFT(F27,2)="OK",0,IF(LEFT(F27,2)="WA",2,1)) -> 0 | G26: =IF(LEFT(G27,2)="OK",0,IF(LEFT(G27,2)="WA",2,1)) -> 0 | H26: =IF(LEFT(H27,2)="OK",0,IF(LEFT(H27,2)="WA",2,1)) -> 0 | ... IP26: =IF(LEFT(IP27,2)="OK",0,IF(LEFT(IP27,2)="WA",2,1)) -> 0
A27: =IF(ABS(Questionnaire!D52-Questionnaire!D68)>1000,"WARNING Q 18.a-18.b - Net affiliates profit/loss is greater than £1000m - please check","OK Q 18.a-18.b") -> OK Q 18.a-18.b | B27: =IF(ABS(Questionnaire!E52-Questionnaire!E68)>1000,"WARNING Q 18.a-18.b - Net affiliates profit/loss is greater than £1000m - please check","OK Q 18.a-18.b") -> OK Q 18.a-18.b | C27: =IF(ABS(Questionnaire!F52-Questionnaire!F68)>1000,"WARNING Q 18.a-18.b - Net affiliates profit/loss is greater than £1000m - please check","OK Q 18.a-18.b") -> OK Q 18.a-18.b | D27: =IF(ABS(Questionnaire!G52-Questionnaire!G68)>1000,"WARNING Q 18.a-18.b - Net affiliates profit/loss is greater than £1000m - please check","OK Q 18.a-18.b") -> OK Q 18.a-18.b | E27: =IF(ABS(Questionnaire!H52-Questionnaire!H68)>1000,"WARNING Q 18.a-18.b - Net affiliates profit/loss is greater than £1000m - please check","OK Q 18.a-18.b") -> OK Q 18.a-18.b | F27: =IF(ABS(Questionnaire!I52-Questionnaire!I68)>1000,"WARNING Q 18.a-18.b - Net affiliates profit/loss is greater than £1000m - please check","OK Q 18.a-18.b") -> OK Q 18.a-18.b | G27: =IF(ABS(Questionnaire!J52-Questionnaire!J68)>1000,"WARNING Q 18.a-18.b - Net affiliates profit/loss is greater than £1000m - please check","OK Q 18.a-18.b") -> OK Q 18.a-18.b | H27: =IF(ABS(Questionnaire!K52-Questionnaire!K68)>1000,"WARNING Q 18.a-18.b - Net affiliates profit/loss is greater than £1000m - please check","OK Q 18.a-18.b") -> OK Q 18.a-18.b | ... IP27: =IF(ABS(Questionnaire!IS52-Questionnaire!IS68)>1000,"WARNING Q 18.a-18.b - Net affiliates profit/loss is greater than £1000m - please check","OK Q 18.a-18.b") -> OK Q 18.a-18.b
A28: =IF(LEFT(A29,2)="OK",0,IF(LEFT(A29,2)="QU",2,1)) -> 0 | B28: =IF(LEFT(B29,2)="OK",0,IF(LEFT(B29,2)="QU",2,1)) -> 0 | C28: =IF(LEFT(C29,2)="OK",0,IF(LEFT(C29,2)="QU",2,1)) -> 0 | D28: =IF(LEFT(D29,2)="OK",0,IF(LEFT(D29,2)="QU",2,1)) -> 0 | E28: =IF(LEFT(E29,2)="OK",0,IF(LEFT(E29,2)="QU",2,1)) -> 0 | F28: =IF(LEFT(F29,2)="OK",0,IF(LEFT(F29,2)="QU",2,1)) -> 0 | G28: =IF(LEFT(G29,2)="OK",0,IF(LEFT(G29,2)="QU",2,1)) -> 0 | H28: =IF(LEFT(H29,2)="OK",0,IF(LEFT(H29,2)="QU",2,1)) -> 0 | ... IP28: =IF(LEFT(IP29,2)="OK",0,IF(LEFT(IP29,2)="QU",2,1)) -> 0
A29: =IF(Questionnaire!D52=(Questionnaire!D54+Questionnaire!D55+Questionnaire!D56+Questionnaire!D57+Questionnaire!D58+Questionnaire!D59+Questionnaire!D60+Questionnaire!D61+Questionnaire!D62+Questionnaire!D63+Questionnaire!D64+Questionnaire!D65+Questionnaire!D66)=TRUE,"OK Q18.a.i","QUERY Q18 - Components in 18a.i must sum to profit in 18.a - please check") -> OK Q18.a.i | B29: =IF(Questionnaire!E52=(Questionnaire!E54+Questionnaire!E55+Questionnaire!E56+Questionnaire!E57+Questionnaire!E58+Questionnaire!E59+Questionnaire!E60+Questionnaire!E61+Questionnaire!E62+Questionnaire!E63+Questionnaire!E64+Questionnaire!E65+Questionnaire!E66)=TRUE,"OK Q18.a.i","QUERY Q18 - Components in 18a.i must sum to profit in 18.a - please check") -> OK Q18.a.i | C29: =IF(Questionnaire!F52=(Questionnaire!F54+Questionnaire!F55+Questionnaire!F56+Questionnaire!F57+Questionnaire!F58+Questionnaire!F59+Questionnaire!F60+Questionnaire!F61+Questionnaire!F62+Questionnaire!F63+Questionnaire!F64+Questionnaire!F65+Questionnaire!F66)=TRUE,"OK Q18.a.i","QUERY Q18 - Components in 18a.i must sum to profit in 18.a - please check") -> OK Q18.a.i | D29: =IF(Questionnaire!G52=(Questionnaire!G54+Questionnaire!G55+Questionnaire!G56+Questionnaire!G57+Questionnaire!G58+Questionnaire!G59+Questionnaire!G60+Questionnaire!G61+Questionnaire!G62+Questionnaire!G63+Questionnaire!G64+Questionnaire!G65+Questionnaire!G66)=TRUE,"OK Q18.a.i","QUERY Q18 - Components in 18a.i must sum to profit in 18.a - please check") -> OK Q18.a.i | E29: =IF(Questionnaire!H52=(Questionnaire!H54+Questionnaire!H55+Questionnaire!H56+Questionnaire!H57+Questionnaire!H58+Questionnaire!H59+Questionnaire!H60+Questionnaire!H61+Questionnaire!H62+Questionnaire!H63+Questionnaire!H64+Questionnaire!H65+Questionnaire!H66)=TRUE,"OK Q18.a.i","QUERY Q18 - Components in 18a.i must sum to profit in 18.a - please check") -> OK Q18.a.i | F29: =IF(Questionnaire!I52=(Questionnaire!I54+Questionnaire!I55+Questionnaire!I56+Questionnaire!I57+Questionnaire!I58+Questionnaire!I59+Questionnaire!I60+Questionnaire!I61+Questionnaire!I62+Questionnaire!I63+Questionnaire!I64+Questionnaire!I65+Questionnaire!I66)=TRUE,"OK Q18.a.i","QUERY Q18 - Components in 18a.i must sum to profit in 18.a - please check") -> OK Q18.a.i | G29: =IF(Questionnaire!J52=(Questionnaire!J54+Questionnaire!J55+Questionnaire!J56+Questionnaire!J57+Questionnaire!J58+Questionnaire!J59+Questionnaire!J60+Questionnaire!J61+Questionnaire!J62+Questionnaire!J63+Questionnaire!J64+Questionnaire!J65+Questionnaire!J66)=TRUE,"OK Q18.a.i","QUERY Q18 - Components in 18a.i must sum to profit in 18.a - please check") -> OK Q18.a.i | H29: =IF(Questionnaire!K52=(Questionnaire!K54+Questionnaire!K55+Questionnaire!K56+Questionnaire!K57+Questionnaire!K58+Questionnaire!K59+Questionnaire!K60+Questionnaire!K61+Questionnaire!K62+Questionnaire!K63+Questionnaire!K64+Questionnaire!K65+Questionnaire!K66)=TRUE,"OK Q18.a.i","QUERY Q18 - Components in 18a.i must sum to profit in 18.a - please check") -> OK Q18.a.i | ... IP29: =IF(Questionnaire!IS52=(Questionnaire!IS54+Questionnaire!IS55+Questionnaire!IS56+Questionnaire!IS57+Questionnaire!IS58+Questionnaire!IS59+Questionnaire!IS60+Questionnaire!IS61+Questionnaire!IS62+Questionnaire!IS63+Questionnaire!IS64+Questionnaire!IS65+Questionnaire!IS66)=TRUE,"OK Q18.a.i","QUERY Q18 - Components in 18a.i must sum to profit in 18.a - please check") -> OK Q18.a.i
A30: =IF(LEFT(A31,2)="OK",0,IF(LEFT(A31,2)="QU",2,1)) -> 2 | B30: =IF(LEFT(B31,2)="OK",0,IF(LEFT(B31,2)="QU",2,1)) -> 0 | C30: =IF(LEFT(C31,2)="OK",0,IF(LEFT(C31,2)="QU",2,1)) -> 0 | D30: =IF(LEFT(D31,2)="OK",0,IF(LEFT(D31,2)="QU",2,1)) -> 0 | E30: =IF(LEFT(E31,2)="OK",0,IF(LEFT(E31,2)="QU",2,1)) -> 0 | F30: =IF(LEFT(F31,2)="OK",0,IF(LEFT(F31,2)="QU",2,1)) -> 0 | G30: =IF(LEFT(G31,2)="OK",0,IF(LEFT(G31,2)="QU",2,1)) -> 0 | H30: =IF(LEFT(H31,2)="OK",0,IF(LEFT(H31,2)="QU",2,1)) -> 0 | ... IP30: =IF(LEFT(IP31,2)="OK",0,IF(LEFT(IP31,2)="QU",2,1)) -> 0
A31: =IF(Questionnaire!D72=0,"OK Q 22",IF((Questionnaire!D72)>(Questionnaire!D52),"QUERY Q 22 - Ordinary Dividends are greater than affiliates profit, re-invested earnings will be negative","OK Q 22")) -> QUERY Q 22 - Ordinary Dividends are greater than affiliates profit, re-invested earnings will be negative | B31: =IF(Questionnaire!E72=0,"OK Q 22",IF((Questionnaire!E72)>(Questionnaire!E52-Questionnaire!E68),"QUERY Q 22 - Ordinary Dividends are greater than affiliates profit, re-invested earnings will be negative","OK Q 22")) -> OK Q 22 | C31: =IF(Questionnaire!F72=0,"OK Q 22",IF((Questionnaire!F72)>(Questionnaire!F52),"QUERY Q 22 - Ordinary Dividends are greater than affiliates profit, re-invested earnings will be negative","OK Q 22")) -> OK Q 22 | D31: =IF(Questionnaire!G72=0,"OK Q 22",IF((Questionnaire!G72)>(Questionnaire!G52),"QUERY Q 22 - Ordinary Dividends are greater than affiliates profit, re-invested earnings will be negative","OK Q 22")) -> OK Q 22 | E31: =IF(Questionnaire!H72=0,"OK Q 22",IF((Questionnaire!H72)>(Questionnaire!H52),"QUERY Q 22 - Ordinary Dividends are greater than affiliates profit, re-invested earnings will be negative","OK Q 22")) -> OK Q 22 | F31: =IF(Questionnaire!I72=0,"OK Q 22",IF((Questionnaire!I72)>(Questionnaire!I52),"QUERY Q 22 - Ordinary Dividends are greater than affiliates profit, re-invested earnings will be negative","OK Q 22")) -> OK Q 22 | G31: =IF(Questionnaire!J72=0,"OK Q 22",IF((Questionnaire!J72)>(Questionnaire!J52),"QUERY Q 22 - Ordinary Dividends are greater than affiliates profit, re-invested earnings will be negative","OK Q 22")) -> OK Q 22 | H31: =IF(Questionnaire!K72=0,"OK Q 22",IF((Questionnaire!K72)>(Questionnaire!K52),"QUERY Q 22 - Ordinary Dividends are greater than affiliates profit, re-invested earnings will be negative","OK Q 22")) -> OK Q 22 | I31: =IF(Questionnaire!L72=0,"OK Q 22",IF((Questionnaire!L72)>(Questionnaire!L52),"QUERY Q 22 - Ordinary Dividends are greater than affiliates profit, re-invested earnings will be negative","OK Q 22")) -> OK Q 22 | J31: =IF(Questionnaire!M72=0,"OK Q 22",IF((Questionnaire!M72)>(Questionnaire!M52),"QUERY Q 22 - Ordinary Dividends are greater than affiliates profit, re-invested earnings will be negative","OK Q 22")) -> OK Q 22 | ... IP31: =IF(Questionnaire!IS72=0,"OK Q 22",IF((Questionnaire!IS72)>(Questionnaire!IS52),"QUERY Q 22 - Ordinary Dividends are greater than affiliates profit, re-invested earnings will be negative","OK Q 22")) -> OK Q 22
A32: =IF(LEFT(A33,2)="OK",0,IF(LEFT(A33,2)="WA",2,1)) -> 2 | B32: =IF(LEFT(B33,2)="OK",0,IF(LEFT(B33,2)="WA",2,1)) -> 0 | C32: =IF(LEFT(C33,2)="OK",0,IF(LEFT(C33,2)="WA",2,1)) -> 0 | D32: =IF(LEFT(D33,2)="OK",0,IF(LEFT(D33,2)="WA",2,1)) -> 0 | E32: =IF(LEFT(E33,2)="OK",0,IF(LEFT(E33,2)="WA",2,1)) -> 0 | F32: =IF(LEFT(F33,2)="OK",0,IF(LEFT(F33,2)="WA",2,1)) -> 0 | G32: =IF(LEFT(G33,2)="OK",0,IF(LEFT(G33,2)="WA",2,1)) -> 0 | H32: =IF(LEFT(H33,2)="OK",0,IF(LEFT(H33,2)="WA",2,1)) -> 0 | ... IP32: =IF(LEFT(IP33,2)="OK",0,IF(LEFT(IP33,2)="WA",2,1)) -> 0
A33: =IF(Questionnaire!D72>100,"WARNING Q 22 - Ordinary Dividends are greater than £100m - please check","OK Q 22") -> WARNING Q 22 - Ordinary Dividends are greater than £100m - please check | B33: =IF(Questionnaire!E72>100,"WARNING Q 22 - Ordinary Dividends are greater than £100m - please check","OK Q 22") -> OK Q 22 | C33: =IF(Questionnaire!F72>100,"WARNING Q 22 - Ordinary Dividends are greater than £100m - please check","OK Q 22") -> OK Q 22 | D33: =IF(Questionnaire!G72>100,"WARNING Q 22 - Ordinary Dividends are greater than £100m - please check","OK Q 22") -> OK Q 22 | E33: =IF(Questionnaire!H72>100,"WARNING Q 22 - Ordinary Dividends are greater than £100m - please check","OK Q 22") -> OK Q 22 | F33: =IF(Questionnaire!I72>100,"WARNING Q 22 - Ordinary Dividends are greater than £100m - please check","OK Q 22") -> OK Q 22 | G33: =IF(Questionnaire!J72>100,"WARNING Q 22 - Ordinary Dividends are greater than £100m - please check","OK Q 22") -> OK Q 22 | H33: =IF(Questionnaire!K72>100,"WARNING Q 22 - Ordinary Dividends are greater than £100m - please check","OK Q 22") -> OK Q 22 | ... IP33: =IF(Questionnaire!IS72>100,"WARNING Q 22 - Ordinary Dividends are greater than £100m - please check","OK Q 22") -> OK Q 22
A34: =IF(LEFT(A35,2)="OK",0,IF(LEFT(A35,2)="QU",2,1)) -> 0 | B34: =IF(LEFT(B35,2)="OK",0,IF(LEFT(B35,2)="QU",2,1)) -> 0 | C34: =IF(LEFT(C35,2)="OK",0,IF(LEFT(C35,2)="QU",2,1)) -> 0 | D34: =IF(LEFT(D35,2)="OK",0,IF(LEFT(D35,2)="QU",2,1)) -> 0 | E34: =IF(LEFT(E35,2)="OK",0,IF(LEFT(E35,2)="QU",2,1)) -> 0 | F34: =IF(LEFT(F35,2)="OK",0,IF(LEFT(F35,2)="QU",2,1)) -> 0 | G34: =IF(LEFT(G35,2)="OK",0,IF(LEFT(G35,2)="QU",2,1)) -> 0 | H34: =IF(LEFT(H35,2)="OK",0,IF(LEFT(H35,2)="QU",2,1)) -> 0 | ... IP34: =IF(LEFT(IP35,2)="OK",0,IF(LEFT(IP35,2)="QU",2,1)) -> 0
A35: =IF(OR(Questionnaire!D80=Questionnaire!D78+Questionnaire!D52-Questionnaire!D68-Questionnaire!D72+Questionnaire!D82-Questionnaire!D95+Questionnaire!D108-Questionnaire!D109,Questionnaire!D75="Unquoted")=TRUE,"OK Q 27","QUERY Q 27 - Closing Quoted Shares - Sum of transactions does not equal closing balance - please check") -> OK Q 27 | B35: =IF(OR(Questionnaire!E80=Questionnaire!E78+Questionnaire!E52-Questionnaire!E68-Questionnaire!E72+Questionnaire!E82-Questionnaire!E95+Questionnaire!E108-Questionnaire!E109,Questionnaire!E75="Unquoted")=TRUE,"OK Q 27","QUERY Q 27 - Closing Quoted Shares - Sum of transactions does not equal closing balance - please check") -> OK Q 27 | C35: =IF(OR(Questionnaire!F80=Questionnaire!F78+Questionnaire!F52-Questionnaire!F68-Questionnaire!F72+Questionnaire!F82-Questionnaire!F95+Questionnaire!F108-Questionnaire!F109,Questionnaire!F75="Unquoted")=TRUE,"OK Q 27","QUERY Q 27 - Closing Quoted Shares - Sum of transactions does not equal closing balance - please check") -> OK Q 27 | D35: =IF(OR(Questionnaire!G80=Questionnaire!G78+Questionnaire!G52-Questionnaire!G68-Questionnaire!G72+Questionnaire!G82-Questionnaire!G95+Questionnaire!G108-Questionnaire!G109,Questionnaire!G75="Unquoted")=TRUE,"OK Q 27","QUERY Q 27 - Closing Quoted Shares - Sum of transactions does not equal closing balance - please check") -> OK Q 27 | E35: =IF(OR(Questionnaire!H80=Questionnaire!H78+Questionnaire!H52-Questionnaire!H68-Questionnaire!H72+Questionnaire!H82-Questionnaire!H95+Questionnaire!H108-Questionnaire!H109,Questionnaire!H75="Unquoted")=TRUE,"OK Q 27","QUERY Q 27 - Closing Quoted Shares - Sum of transactions does not equal closing balance - please check") -> OK Q 27 | F35: =IF(OR(Questionnaire!I80=Questionnaire!I78+Questionnaire!I52-Questionnaire!I68-Questionnaire!I72+Questionnaire!I82-Questionnaire!I95+Questionnaire!I108-Questionnaire!I109,Questionnaire!I75="Unquoted")=TRUE,"OK Q 27","QUERY Q 27 - Closing Quoted Shares - Sum of transactions does not equal closing balance - please check") -> OK Q 27 | G35: =IF(OR(Questionnaire!J80=Questionnaire!J78+Questionnaire!J52-Questionnaire!J68-Questionnaire!J72+Questionnaire!J82-Questionnaire!J95+Questionnaire!J108-Questionnaire!J109,Questionnaire!J75="Unquoted")=TRUE,"OK Q 27","QUERY Q 27 - Closing Quoted Shares - Sum of transactions does not equal closing balance - please check") -> OK Q 27 | H35: =IF(OR(Questionnaire!K80=Questionnaire!K78+Questionnaire!K52-Questionnaire!K68-Questionnaire!K72+Questionnaire!K82-Questionnaire!K95+Questionnaire!K108-Questionnaire!K109,Questionnaire!K75="Unquoted")=TRUE,"OK Q 27","QUERY Q 27 - Closing Quoted Shares - Sum of transactions does not equal closing balance - please check") -> OK Q 27 | ... IP35: =IF(OR(Questionnaire!IS80=Questionnaire!IS78+Questionnaire!IS52-Questionnaire!IS68-Questionnaire!IS72+Questionnaire!IS82-Questionnaire!IS95+Questionnaire!IS108-Questionnaire!IS109,Questionnaire!IS75="Unquoted")=TRUE,"OK Q 27","QUERY Q 27 - Closing Quoted Shares - Sum of transactions does not equal closing balance - please check") -> OK Q 27
A36: =IF(LEFT(A37,2)="OK",0,IF(LEFT(A37,2)="QU",2,1)) -> 0 | B36: =IF(LEFT(B37,2)="OK",0,IF(LEFT(B37,2)="QU",2,1)) -> 0 | C36: =IF(LEFT(C37,2)="OK",0,IF(LEFT(C37,2)="QU",2,1)) -> 0 | D36: =IF(LEFT(D37,2)="OK",0,IF(LEFT(D37,2)="QU",2,1)) -> 0 | E36: =IF(LEFT(E37,2)="OK",0,IF(LEFT(E37,2)="QU",2,1)) -> 0 | F36: =IF(LEFT(F37,2)="OK",0,IF(LEFT(F37,2)="QU",2,1)) -> 0 | G36: =IF(LEFT(G37,2)="OK",0,IF(LEFT(G37,2)="QU",2,1)) -> 0 | H36: =IF(LEFT(H37,2)="OK",0,IF(LEFT(H37,2)="QU",2,1)) -> 0 | ... IP36: =IF(LEFT(IP37,2)="OK",0,IF(LEFT(IP37,2)="QU",2,1)) -> 0
A37: =IF(Questionnaire!D82=(Questionnaire!D84+Questionnaire!D85+Questionnaire!D86+Questionnaire!D87)=TRUE,"OK Q29.a.i","QUERY Q29a - Components in 29.a.i must sum to acquisitions of quoted equity capital total value in 29.a - please check") -> OK Q29.a.i | B37: =IF(Questionnaire!E82=(Questionnaire!E84+Questionnaire!E85+Questionnaire!E86+Questionnaire!E87)=TRUE,"OK Q29.a.i","QUERY Q29a - Components in 29.a.i must sum to acquisitions of quoted equity capital total value in 29.a - please check") -> OK Q29.a.i | C37: =IF(Questionnaire!F82=(Questionnaire!F84+Questionnaire!F85+Questionnaire!F86+Questionnaire!F87)=TRUE,"OK Q29.a.i","QUERY Q29a - Components in 29.a.i must sum to acquisitions of quoted equity capital total value in 29.a - please check") -> OK Q29.a.i | D37: =IF(Questionnaire!G82=(Questionnaire!G84+Questionnaire!G85+Questionnaire!G86+Questionnaire!G87)=TRUE,"OK Q29.a.i","QUERY Q29a - Components in 29.a.i must sum to acquisitions of quoted equity capital total value in 29.a - please check") -> OK Q29.a.i | E37: =IF(Questionnaire!H82=(Questionnaire!H84+Questionnaire!H85+Questionnaire!H86+Questionnaire!H87)=TRUE,"OK Q29.a.i","QUERY Q29a - Components in 29.a.i must sum to acquisitions of quoted equity capital total value in 29.a - please check") -> OK Q29.a.i | F37: =IF(Questionnaire!I82=(Questionnaire!I84+Questionnaire!I85+Questionnaire!I86+Questionnaire!I87)=TRUE,"OK Q29.a.i","QUERY Q29a - Components in 29.a.i must sum to acquisitions of quoted equity capital total value in 29.a - please check") -> OK Q29.a.i | G37: =IF(Questionnaire!J82=(Questionnaire!J84+Questionnaire!J85+Questionnaire!J86+Questionnaire!J87)=TRUE,"OK Q29.a.i","QUERY Q29a - Components in 29.a.i must sum to acquisitions of quoted equity capital total value in 29.a - please check") -> OK Q29.a.i | H37: =IF(Questionnaire!K82=(Questionnaire!K84+Questionnaire!K85+Questionnaire!K86+Questionnaire!K87)=TRUE,"OK Q29.a.i","QUERY Q29a - Components in 29.a.i must sum to acquisitions of quoted equity capital total value in 29.a - please check") -> OK Q29.a.i | ... IP37: =IF(Questionnaire!IS82=(Questionnaire!IS84+Questionnaire!IS85+Questionnaire!IS86+Questionnaire!IS87)=TRUE,"OK Q29.a.i","QUERY Q29a - Components in 29.a.i must sum to acquisitions of quoted equity capital total value in 29.a - please check") -> OK Q29.a.i
A38: =IF(LEFT(A39,2)="OK",0,IF(LEFT(A39,2)="QU",2,1)) -> 0 | B38: =IF(LEFT(B39,2)="OK",0,IF(LEFT(B39,2)="QU",2,1)) -> 0 | C38: =IF(LEFT(C39,2)="OK",0,IF(LEFT(C39,2)="QU",2,1)) -> 0 | D38: =IF(LEFT(D39,2)="OK",0,IF(LEFT(D39,2)="QU",2,1)) -> 0 | E38: =IF(LEFT(E39,2)="OK",0,IF(LEFT(E39,2)="QU",2,1)) -> 0 | F38: =IF(LEFT(F39,2)="OK",0,IF(LEFT(F39,2)="QU",2,1)) -> 0 | G38: =IF(LEFT(G39,2)="OK",0,IF(LEFT(G39,2)="QU",2,1)) -> 0 | H38: =IF(LEFT(H39,2)="OK",0,IF(LEFT(H39,2)="QU",2,1)) -> 0 | ... IP38: =IF(LEFT(IP39,2)="OK",0,IF(LEFT(IP39,2)="QU",2,1)) -> 0
A39: =IF(Questionnaire!D82=(Questionnaire!D90+Questionnaire!D91+Questionnaire!D92+Questionnaire!D93)=TRUE,"OK Q29.a.ii","QUERY Q29a - Components in 29.a.ii must sum to acquisitions of quoted equity capital total value in 29.a - please check") -> OK Q29.a.ii | B39: =IF(Questionnaire!E82=(Questionnaire!E90+Questionnaire!E91+Questionnaire!E92+Questionnaire!E93)=TRUE,"OK Q29.a.ii","QUERY Q29a - Components in 29.a.ii must sum to acquisitions of quoted equity capital total value in 29.a - please check") -> OK Q29.a.ii | C39: =IF(Questionnaire!F82=(Questionnaire!F90+Questionnaire!F91+Questionnaire!F92+Questionnaire!F93)=TRUE,"OK Q29.a.ii","QUERY Q29a - Components in 29.a.ii must sum to acquisitions of quoted equity capital total value in 29.a - please check") -> OK Q29.a.ii | D39: =IF(Questionnaire!G82=(Questionnaire!G90+Questionnaire!G91+Questionnaire!G92+Questionnaire!G93)=TRUE,"OK Q29.a.ii","QUERY Q29a - Components in 29.a.ii must sum to acquisitions of quoted equity capital total value in 29.a - please check") -> OK Q29.a.ii | E39: =IF(Questionnaire!H82=(Questionnaire!H90+Questionnaire!H91+Questionnaire!H92+Questionnaire!H93)=TRUE,"OK Q29.a.ii","QUERY Q29a - Components in 29.a.ii must sum to acquisitions of quoted equity capital total value in 29.a - please check") -> OK Q29.a.ii | F39: =IF(Questionnaire!I82=(Questionnaire!I90+Questionnaire!I91+Questionnaire!I92+Questionnaire!I93)=TRUE,"OK Q29.a.ii","QUERY Q29a - Components in 29.a.ii must sum to acquisitions of quoted equity capital total value in 29.a - please check") -> OK Q29.a.ii | G39: =IF(Questionnaire!J82=(Questionnaire!J90+Questionnaire!J91+Questionnaire!J92+Questionnaire!J93)=TRUE,"OK Q29.a.ii","QUERY Q29a - Components in 29.a.ii must sum to acquisitions of quoted equity capital total value in 29.a - please check") -> OK Q29.a.ii | H39: =IF(Questionnaire!K82=(Questionnaire!K90+Questionnaire!K91+Questionnaire!K92+Questionnaire!K93)=TRUE,"OK Q29.a.ii","QUERY Q29a - Components in 29.a.ii must sum to acquisitions of quoted equity capital total value in 29.a - please check") -> OK Q29.a.ii | ... IP39: =IF(Questionnaire!IS82=(Questionnaire!IS90+Questionnaire!IS91+Questionnaire!IS92+Questionnaire!IS93)=TRUE,"OK Q29.a.ii","QUERY Q29a - Components in 29.a.ii must sum to acquisitions of quoted equity capital total value in 29.a - please check") -> OK Q29.a.ii
A40: =IF(LEFT(A41,2)="OK",0,IF(LEFT(A41,2)="QU",2,1)) -> 0 | B40: =IF(LEFT(B41,2)="OK",0,IF(LEFT(B41,2)="QU",2,1)) -> 0 | C40: =IF(LEFT(C41,2)="OK",0,IF(LEFT(C41,2)="QU",2,1)) -> 0 | D40: =IF(LEFT(D41,2)="OK",0,IF(LEFT(D41,2)="QU",2,1)) -> 0 | E40: =IF(LEFT(E41,2)="OK",0,IF(LEFT(E41,2)="QU",2,1)) -> 0 | F40: =IF(LEFT(F41,2)="OK",0,IF(LEFT(F41,2)="QU",2,1)) -> 0 | G40: =IF(LEFT(G41,2)="OK",0,IF(LEFT(G41,2)="QU",2,1)) -> 0 | H40: =IF(LEFT(H41,2)="OK",0,IF(LEFT(H41,2)="QU",2,1)) -> 0 | ... IP40: =IF(LEFT(IP41,2)="OK",0,IF(LEFT(IP41,2)="QU",2,1)) -> 0
A41: =IF(Questionnaire!D95=(Questionnaire!D97+Questionnaire!D98+Questionnaire!D99)=TRUE,"OK Q29.b.i","QUERY Q29b - Components in 29.b.i must sum to disposal of quoted equity capital total value in 29.b - please check") -> OK Q29.b.i | B41: =IF(Questionnaire!E95=(Questionnaire!E97+Questionnaire!E98+Questionnaire!E99)=TRUE,"OK Q29.b.i","QUERY Q29b - Components in 29.b.i must sum to disposal of quoted equity capital total value in 29.b - please check") -> OK Q29.b.i | C41: =IF(Questionnaire!F95=(Questionnaire!F97+Questionnaire!F98+Questionnaire!F99)=TRUE,"OK Q29.b.i","QUERY Q29b - Components in 29.b.i must sum to disposal of quoted equity capital total value in 29.b - please check") -> OK Q29.b.i | D41: =IF(Questionnaire!G95=(Questionnaire!G97+Questionnaire!G98+Questionnaire!G99)=TRUE,"OK Q29.b.i","QUERY Q29b - Components in 29.b.i must sum to disposal of quoted equity capital total value in 29.b - please check") -> OK Q29.b.i | E41: =IF(Questionnaire!H95=(Questionnaire!H97+Questionnaire!H98+Questionnaire!H99)=TRUE,"OK Q29.b.i","QUERY Q29b - Components in 29.b.i must sum to disposal of quoted equity capital total value in 29.b - please check") -> OK Q29.b.i | F41: =IF(Questionnaire!I95=(Questionnaire!I97+Questionnaire!I98+Questionnaire!I99)=TRUE,"OK Q29.b.i","QUERY Q29b - Components in 29.b.i must sum to disposal of quoted equity capital total value in 29.b - please check") -> OK Q29.b.i | G41: =IF(Questionnaire!J95=(Questionnaire!J97+Questionnaire!J98+Questionnaire!J99)=TRUE,"OK Q29.b.i","QUERY Q29b - Components in 29.b.i must sum to disposal of quoted equity capital total value in 29.b - please check") -> OK Q29.b.i | H41: =IF(Questionnaire!K95=(Questionnaire!K97+Questionnaire!K98+Questionnaire!K99)=TRUE,"OK Q29.b.i","QUERY Q29b - Components in 29.b.i must sum to disposal of quoted equity capital total value in 29.b - please check") -> OK Q29.b.i | ... IP41: =IF(Questionnaire!IS95=(Questionnaire!IS97+Questionnaire!IS98+Questionnaire!IS99)=TRUE,"OK Q29.b.i","QUERY Q29b - Components in 29.b.i must sum to disposal of quoted equity capital total value in 29.b - please check") -> OK Q29.b.i
A42: =IF(LEFT(A43,2)="OK",0,IF(LEFT(A43,2)="QU",2,1)) -> #REF! | B42: =IF(LEFT(B43,2)="OK",0,IF(LEFT(B43,2)="QU",2,1)) -> 0 | C42: =IF(LEFT(C43,2)="OK",0,IF(LEFT(C43,2)="QU",2,1)) -> 0 | D42: =IF(LEFT(D43,2)="OK",0,IF(LEFT(D43,2)="QU",2,1)) -> 0 | E42: =IF(LEFT(E43,2)="OK",0,IF(LEFT(E43,2)="QU",2,1)) -> 0 | F42: =IF(LEFT(F43,2)="OK",0,IF(LEFT(F43,2)="QU",2,1)) -> 0 | G42: =IF(LEFT(G43,2)="OK",0,IF(LEFT(G43,2)="QU",2,1)) -> 0 | H42: =IF(LEFT(H43,2)="OK",0,IF(LEFT(H43,2)="QU",2,1)) -> 0 | ... IP42: =IF(LEFT(IP43,2)="OK",0,IF(LEFT(IP43,2)="QU",2,1)) -> 0
A43: =IF(Questionnaire!D95=(Questionnaire!D102+Questionnaire!D103+Questionnaire!#REF!+Questionnaire!D104)=TRUE,"OK Q29.b.ii","QUERY Q29b - Components in 29.b.ii must sum to disposal of quoted equity capital total value in 29.b - please check") -> #REF! | B43: =IF(Questionnaire!E95=(Questionnaire!E102+Questionnaire!E103+Questionnaire!E104+Questionnaire!E105)=TRUE,"OK Q29.b.ii","QUERY Q29b - Components in 29.b.ii must sum to disposal of quoted equity capital total value in 29.b - please check") -> OK Q29.b.ii | C43: =IF(Questionnaire!F95=(Questionnaire!F102+Questionnaire!F103+Questionnaire!F104+Questionnaire!F105)=TRUE,"OK Q29.b.ii","QUERY Q29b - Components in 29.b.ii must sum to disposal of quoted equity capital total value in 29.b - please check") -> OK Q29.b.ii | D43: =IF(Questionnaire!G95=(Questionnaire!G102+Questionnaire!G103+Questionnaire!G104+Questionnaire!G105)=TRUE,"OK Q29.b.ii","QUERY Q29b - Components in 29.b.ii must sum to disposal of quoted equity capital total value in 29.b - please check") -> OK Q29.b.ii | E43: =IF(Questionnaire!H95=(Questionnaire!H102+Questionnaire!H103+Questionnaire!H104+Questionnaire!H105)=TRUE,"OK Q29.b.ii","QUERY Q29b - Components in 29.b.ii must sum to disposal of quoted equity capital total value in 29.b - please check") -> OK Q29.b.ii | F43: =IF(Questionnaire!I95=(Questionnaire!I102+Questionnaire!I103+Questionnaire!I104+Questionnaire!I105)=TRUE,"OK Q29.b.ii","QUERY Q29b - Components in 29.b.ii must sum to disposal of quoted equity capital total value in 29.b - please check") -> OK Q29.b.ii | G43: =IF(Questionnaire!J95=(Questionnaire!J102+Questionnaire!J103+Questionnaire!J104+Questionnaire!J105)=TRUE,"OK Q29.b.ii","QUERY Q29b - Components in 29.b.ii must sum to disposal of quoted equity capital total value in 29.b - please check") -> OK Q29.b.ii | H43: =IF(Questionnaire!K95=(Questionnaire!K102+Questionnaire!K103+Questionnaire!K104+Questionnaire!K105)=TRUE,"OK Q29.b.ii","QUERY Q29b - Components in 29.b.ii must sum to disposal of quoted equity capital total value in 29.b - please check") -> OK Q29.b.ii | I43: =IF(Questionnaire!L95=(Questionnaire!L102+Questionnaire!L103+Questionnaire!L104+Questionnaire!L105)=TRUE,"OK Q29.b.ii","QUERY Q29b - Components in 29.b.ii must sum to disposal of quoted equity capital total value in 29.b - please check") -> OK Q29.b.ii | ... IP43: =IF(Questionnaire!IS95=(Questionnaire!IS102+Questionnaire!IS103+Questionnaire!IS104+Questionnaire!IS105)=TRUE,"OK Q29.b.ii","QUERY Q29b - Components in 29.b.ii must sum to disposal of quoted equity capital total value in 29.b - please check") -> OK Q29.b.ii
A44: =IF(LEFT(A45,2)="OK",0,IF(LEFT(A45,2)="WA",2,1)) -> 2 | B44: =IF(LEFT(B45,2)="OK",0,IF(LEFT(B45,2)="WA",2,1)) -> 0 | C44: =IF(LEFT(C45,2)="OK",0,IF(LEFT(C45,2)="WA",2,1)) -> 0 | D44: =IF(LEFT(D45,2)="OK",0,IF(LEFT(D45,2)="WA",2,1)) -> 0 | E44: =IF(LEFT(E45,2)="OK",0,IF(LEFT(E45,2)="WA",2,1)) -> 0 | F44: =IF(LEFT(F45,2)="OK",0,IF(LEFT(F45,2)="WA",2,1)) -> 0 | G44: =IF(LEFT(G45,2)="OK",0,IF(LEFT(G45,2)="WA",2,1)) -> 0 | H44: =IF(LEFT(H45,2)="OK",0,IF(LEFT(H45,2)="WA",2,1)) -> 0 | ... IP44: =IF(LEFT(IP45,2)="OK",0,IF(LEFT(IP45,2)="WA",2,1)) -> 0
...

Sheet Country List
A1: Options for the country sector drop-down boxes
A2: Country code | B2: Country description | D2: Country code | E2: Immediate country description
E3: Non-UK
B4: AFGHANISTAN | C4: 609 | E4: AFGHANISTAN | F4: 609
B5: ALBANIA | C5: 514 | E5: ALBANIA | F5: 514
B6: ALGERIA | C6: 118 | E6: ALGERIA | F6: 118
B7: AMERICAN SAMOA | C7: 641 | E7: AMERICAN SAMOA | F7: 641
B8: ANDORRA | C8: 522 | E8: ANDORRA | F8: 522
B9: ANGOLA | C9: 2 | E9: ANGOLA | F9: 2
B10: ANGUILLA | C10: 821 | E10: ANGUILLA | F10: 821
